



args_dataset here: DatasetDict({
    train: Dataset({
        features: ['metadata', 'target_object', 'chat'],
        num_rows: 100000
    })
})




Traceback (most recent call last):
  File "/Users/aditi/Documents/multiturn-20q/collab-llm/scripts/generate_conv_dpo_20q.py", line 414, in <module>
    main()
  File "/Users/aditi/Documents/multiturn-20q/collab-llm/scripts/generate_conv_dpo_20q.py", line 318, in main
    idx_all = [i for i in range(len(dataset[split]))]
                                    ~~~~~~~^^^^^^^
  File "/Users/aditi/Documents/multiturn-20q/20q/lib/python3.12/site-packages/datasets/arrow_dataset.py", line 2777, in __getitem__
    return self._getitem(key)
           ^^^^^^^^^^^^^^^^^^
  File "/Users/aditi/Documents/multiturn-20q/20q/lib/python3.12/site-packages/datasets/arrow_dataset.py", line 2761, in _getitem
    pa_subtable = query_table(self._data, key, indices=self._indices)
                  ^^^^^^^^^^^^^^^^^^^^^^^^^^^^^^^^^^^^^^^^^^^^^^^^^^^
  File "/Users/aditi/Documents/multiturn-20q/20q/lib/python3.12/site-packages/datasets/formatting/formatting.py", line 609, in query_table
    _check_valid_column_key(key, table.column_names)
  File "/Users/aditi/Documents/multiturn-20q/20q/lib/python3.12/site-packages/datasets/formatting/formatting.py", line 546, in _check_valid_column_key
    raise KeyError(f"Column {key} not in the dataset. Current columns in the dataset: {columns}")
KeyError: "Column train not in the dataset. Current columns in the dataset: ['metadata', 'target_object', 'chat']"
